Workbook

Sheet Inadimplencia - FEV 2025
A1: Relatorio de inadimplencia - Fev/2025
A2: TOTAL INADIMPLÊNCIA: | E2: =SUM(D5:D85) -> 3377637 | F2: =SUM(F5:F85) -> 81 | I2: =VLOOKUP(H5,A9:C35,2,0) -> #N/A
A3: Etapa/Unidade | B3: Qtde | C3: Valor principal | D3: Valor Corrigido | E3: Multas/Juros
C4: =SUM(C5:C85) -> 436666.86 | D4: =SUM(D5:D85) -> 3377637 | E4: =SUM(E5:E85) -> 2940970.1 | H4: Referencia | I4: Inadimplencia - FEV 2025
A5: OR016 | B5: 179 | C5: 47546.02 | D5: 1957145.6 | E5: =D5-C5 -> 1909599.5 | F5: 1 | H5: OR016 | I5: =VLOOKUP(H5,A5:E85,5,0) -> 1909599.5
A6: JA052 | B6: 154 | C6: 62651.41 | D6: 708179.44 | E6: =D6-C6 -> 645528.03 | F6: 1 | H6: AZ002
A7: OR006 | B7: 68 | C7: 29182.02 | D7: 290586.5 | E7: =D7-C7 -> 261404.48 | F7: 1 | H7: AZ003
A8: PI033 | B8: 83 | C8: 38226.46 | D8: 77430.58 | E8: =D8-C8 -> 39204.12 | F8: 1 | H8: AZ004
A9: GA022 | B9: 42 | C9: 19262.28 | D9: 39786.05 | E9: =D9-C9 -> 20523.77 | F9: 1 | H9: AZ005
A10: AZ010 | B10: 41 | C10: 19485.69 | D10: 26509.09 | E10: =D10-C10 -> 7023.4 | F10: 1 | H10: AZ006
A11: OR060 | B11: 3 | C11: 1207.49 | D11: 24521.38 | E11: =D11-C11 -> 23313.89 | F11: 1 | H11: AZ007
A12: AZ001 | B12: 10 | C12: 15193.4 | D12: 16769.17 | E12: =D12-C12 -> 1575.77 | F12: 1 | H12: AZ008
A13: PI057 | B13: 13 | C13: 8690.27 | D13: 12654.41 | E13: =D13-C13 -> 3964.14 | F13: 1 | H13: AZ009
A14: BO078 | B14: 19 | C14: 9918.81 | D14: 12220.13 | E14: =D14-C14 -> 2301.32 | F14: 1 | H14: AZ010
A15: JA033 | B15: 17 | C15: 8147.26 | D15: 10618.13 | E15: =D15-C15 -> 2470.87 | F15: 1 | H15: AZ011
A16: BO055 | B16: 10 | C16: 9458.1 | D16: 10583.76 | E16: =D16-C16 -> 1125.66 | F16: 1 | H16: AZ012
A17: AZ008 | B17: 16 | C17: 8180 | D17: 9873.38 | E17: =D17-C17 -> 1693.38 | F17: 1 | H17: AZ013
... A85: AZ064 | B85: 1 | C85: 530 | D85: 544.7 | E85: =D85-C85 -> 14.7 | F85: 1 | H85: AZ081
F86: =SUM(F5:F85) -> 81 | H86: AZ082
F87: =F86/549 -> 0.14754098 | H87: AZ083
H88: AZ084
H89: AZ085
H90: AZ086
H91: AZ087
H92: AZ088
H93: AZ089
H94: AZ090
H95: AZ091
H96: AZ092
H97: AZ093
H98: AZ094
H99: AZ095
... H551: PI094

Sheet Inadimplencia - Out 2025
A1: Relatorio de inadimplencia - OUT/2025
A2: TOTAL INADIMPLÊNCIA: | E2: =SUM(D5:D82) -> 3524023.2
A3: Etapa/Unidade | B3: Qtde | C3: Valor principal | D3: Valor Corrigido | E3: Multas/Juros
C4: =SUM(C5:C82) -> 479127.52 | D4: =SUM(D5:D82) -> 3524023.2 | E4: =SUM(E5:E82) -> 3046084 | F4: =SUM(F5:F82) -> 78
A5: OR016 | B5: 179 | C5: 47546.02 | D5: 2026502.2 | E5: =D5-C5 -> 1978956.1 | F5: 1
A6: JA052 | B6: 161 | C6: 66361.41 | D6: 750018.05 | E6: =D6-C6 -> 683656.64 | F6: 1
A7: OR006 | B7: 73 | C7: 31832.02 | D7: 311541.51 | E7: =D7-C7 -> 279709.49 | F7: 1
A8: OR060 | B8: 3 | C8: 1207.49 | D8: 26113.46 | E8: =D8-C8 -> 24905.97 | F8: 1
A9: GA022 | B9: 43 | C9: 19792.28 | D9: 42078.51 | E9: =D9-C9 -> 22286.23 | F9: 1
A10: AZ010 | B10: 48 | C10: 23195.69 | D10: 31815.66 | E10: =D10-C10 -> 8619.97 | F10: 1
A11: PI057 | B11: 17 | C11: 10810.27 | D11: 15565.89 | E11: =D11-C11 -> 4755.62 | F11: 1
A12: BO078 | B12: 26 | C12: 13628.81 | D12: 17241.53 | E12: =D12-C12 -> 3612.72 | F12: 1
A13: AZ001 | B13: 17 | C13: 25828.78 | D13: =C13+431.21+556.04+2152.92 -> 28968.95 | E13: =D13-C13 -> 3140.17 | F13: 1
A14: JA033 | B14: 18 | C14: 8677.26 | D14: 11775.96 | E14: =D14-C14 -> 3098.7 | F14: 1
A15: AZBAR | B15: 11 | C15: 4921.24 | D15: 7582.77 | E15: =D15-C15 -> 2661.53 | F15: 1
A16: BO055 | B16: 25 | C16: 20734.58 | D16: 23136.52 | E16: =D16-C16 -> 2401.94 | F16: 1
A17: AZ008 | B17: 19 | C17: 9770 | D17: 12140.85 | E17: =D17-C17 -> 2370.85 | F17: 1
A18: JA016 | B18: 20 | C18: 10330 | D18: 12567.56 | E18: =D18-C18 -> 2237.56 | F18: 1
A19: AZ039 | B19: 18 | C19: 9270 | D19: 11456.08 | E19: =D19-C19 -> 2186.08 | F19: 1
A20: AZ023 | B20: 16 | C20: 8240 | D20: 10217.63 | E20: =D20-C20 -> 1977.63 | F20: 1
A21: GA040 | B21: 18 | C21: 8546.35 | D21: 10431.86 | E21: =D21-C21 -> 1885.51 | F21: 1
A22: AZ093 | B22: 16 | C22: 10059.29 | D22: 11929 | E22: =D22-C22 -> 1869.71 | F22: 1
A23: PI072 | B23: 21 | C23: 10980 | D23: 12665.32 | E23: =D23-C23 -> 1685.32 | F23: 1
A24: AZ009 | B24: 14 | C24: 7210 | D24: 8868.32 | E24: =D24-C24 -> 1658.32 | F24: 1
A25: GA055 | B25: 16 | C25: 8240 | D25: 9460.95 | E25: =D25-C25 -> 1220.95 | F25: 1
... A29: AZ005 | B29: 13 | C29: 6890 | D29: 7541.22 | E29: =D29-C29 -> 651.22 | F29: 1
A30: GA004 | B30: 1 | C30: 530 | D30: 571.68 | E30: 643.81 | F30: 1
A31: GA073 | B31: 1 | C31: 530 | D31: 587.66 | E31: 643.81 | F31: 1
A32: AZ087 | B32: 20 | C32: 7535.86 | D32: 8065.15 | E32: =D32-C32 -> 529.29 | F32: 1
A33: AZ070 | B33: 7 | C33: 4746.29 | D33: 5240.42 | E33: =D33-C33 -> 494.13 | F33: 1
A34: AZ047 | B34: 27 | C34: 7579.61 | D34: 8047.12 | E34: =D34-C34 -> 467.51 | F34: 1
A35: AZ058 | B35: 14 | C35: 5843.25 | D35: 6202.21 | E35: =D35-C35 -> 358.96 | F35: 1
A36: OR071 | B36: 9 | C36: 4770 | D36: 5084 | E36: =D36-C36 -> 314 | F36: 1
A37: OR047 | B37: 3 | C37: 1782.62 | D37: 2035.7 | E37: =D37-C37 -> 253.08 | F37: 1
A38: OR028 | B38: 4 | C38: 4664.92 | D38: 4917.11 | E38: =D38-C38 -> 252.19 | F38: 1
A39: PI004 | B39: 7 | C39: 3710 | D39: 3936.36 | E39: =D39-C39 -> 226.36 | F39: 1
A40: OR020 | B40: 5 | C40: 2650 | D40: 2875.25 | E40: =D40-C40 -> 225.25 | F40: 1
A41: AZ059 | B41: 2 | C41: 1030 | D41: 1235.1 | E41: =D41-C41 -> 205.1 | F41: 1
A42: AZ026 | B42: 6 | C42: 3180 | D42: 3375.61 | E42: =D42-C42 -> 195.61 | F42: 1
A43: GA046 | B43: 6 | C43: 3180 | D43: 3366.22 | E43: =D43-C43 -> 186.22 | F43: 1
...

Sheet Comparativa
K1: =SUM(K3:K550) -> 3377637 | L1: =SUM(L3:L550) -> 3524023.2 | M1: =L1-K1 -> 146386.24
A2: INDICADOR | B2: CPF | C2: Proprietário | D2: Etapa | E2: Unidade | F2: Nº Quartos | G2: Tipo de Unidade | H2: Capacidade | I2: Documento | J2: Referencia | K2: Inadimplencia - FEV 2025 | L2: Inadimplencia - OUT 2025 | M2: Diferença | N2: Situação
B3: 026.829.151-91 | C3: CASIMILDO FERREIRA DIAS | D3: Orquídeas - OR | E3: 16 | F3: 2 | G3: Residência | H3: 8 | J3: ="OR" & TEXT(E3, "000") -> OR016 | K3: =IFERROR(VLOOKUP(J3,'Inadimplencia - FEV 2025'!$A$5:$E$85,4,0),"0") -> 1957145.6 | L3: =IFERROR(VLOOKUP(J3,'Inadimplencia - Out 2025'!$A$5:$E$85,4,0),"0") -> 2026502.2 | M3: =L3-K3 -> 69356.61 | N3: =IF(L3>K3,"AUMENTOU","DIMINUIU") -> AUMENTOU
B4: 469.420.681-87 | C4: FRANCISCO MEDEIROS DE ARAUJO | D4: Jacarandás - JAC | E4: 52 | F4: 2 | G4: Residência | H4: 8 | J4: ="JA" & TEXT(E4, "000") -> JA052 | K4: =IFERROR(VLOOKUP(J4,'Inadimplencia - FEV 2025'!$A$5:$E$85,4,0),"0") -> 708179.44 | L4: =IFERROR(VLOOKUP(J4,'Inadimplencia - Out 2025'!$A$5:$E$85,4,0),"0") -> 750018.05 | M4: =L4-K4 -> 41838.61 | N4: =IF(L4>K4,"AUMENTOU","DIMINUIU") -> AUMENTOU
B5: 003.080.131-15 | C5: ALFREDO DAIR FERNANDES | D5: Orquídeas - OR | E5: 6 | F5: 2 | G5: Residência | H5: 8 | J5: ="OR" & TEXT(E5, "000") -> OR006 | K5: =IFERROR(VLOOKUP(J5,'Inadimplencia - FEV 2025'!$A$5:$E$85,4,0),"0") -> 290586.5 | L5: =IFERROR(VLOOKUP(J5,'Inadimplencia - Out 2025'!$A$5:$E$85,4,0),"0") -> 311541.51 | M5: =L5-K5 -> 20955.01 | N5: =IF(L5>K5,"AUMENTOU","DIMINUIU") -> AUMENTOU
B6: 042.641.856-53 | C6: MARILENE BATISTA SILVA DE GODOI | D6: Gardênia - GA | E6: 22 | F6: 2 | G6: Residência | H6: 8 | J6: ="GA" & TEXT(E6, "000") -> GA022 | K6: =IFERROR(VLOOKUP(J6,'Inadimplencia - FEV 2025'!$A$5:$E$85,4,0),"0") -> 39786.05 | L6: =IFERROR(VLOOKUP(J6,'Inadimplencia - Out 2025'!$A$5:$E$85,4,0),"0") -> 42078.51 | M6: =L6-K6 -> 2292.46 | N6: =IF(L6>K6,"AUMENTOU","DIMINUIU") -> AUMENTOU
B7: 153.472.731-00 | C7: LUCIMAR LISBOA DA CUNHA LEMES | D7: Azaléia - AZ | E7: 10 | F7: 2 | G7: Residência | H7: 8 | J7: ="AZ" & TEXT(E7, "000") -> AZ010 | K7: =IFERROR(VLOOKUP(J7,'Inadimplencia - FEV 2025'!$A$5:$E$85,4,0),"0") -> 26509.09 | L7: =IFERROR(VLOOKUP(J7,'Inadimplencia - Out 2025'!$A$5:$E$85,4,0),"0") -> 31815.66 | M7: =L7-K7 -> 5306.57 | N7: =IF(L7>K7,"AUMENTOU","DIMINUIU") -> AUMENTOU
B8: 054.909.011-87 | C8: MARCELO GRACIA CANASSA | D8: Orquídeas - OR | E8: 60 | F8: 2 | G8: Residência | H8: 8 | J8: ="OR" & TEXT(E8, "000") -> OR060 | K8: =IFERROR(VLOOKUP(J8,'Inadimplencia - FEV 2025'!$A$5:$E$85,4,0),"0") -> 24521.38 | L8: =IFERROR(VLOOKUP(J8,'Inadimplencia - Out 2025'!$A$5:$E$85,4,0),"0") -> 26113.46 | M8: =L8-K8 -> 1592.08 | N8: =IF(L8>K8,"AUMENTOU","DIMINUIU") -> AUMENTOU
B9: 059.604.601-49 | C9: MARIA MICHELINE COSTA VIEIRA | D9: Azaléia - AZ | E9: 1 | F9: 2 | G9: Residência | H9: 8 | J9: ="AZ" & TEXT(E9, "000") -> AZ001 | K9: =IFERROR(VLOOKUP(J9,'Inadimplencia - FEV 2025'!$A$5:$E$85,4,0),"0") -> 16769.17 | L9: =IFERROR(VLOOKUP(J9,'Inadimplencia - Out 2025'!$A$5:$E$85,4,0),"0") -> 28968.95 | M9: =L9-K9 -> 12199.78 | N9: =IF(L9>K9,"AUMENTOU","DIMINUIU") -> AUMENTOU
B10: 059.604.601-49 | C10: JOSÉ MARIA FRAZÃO | D10: Pitangueiras - PIT | E10: 57 | F10: 2 | G10: Locação Temporária | H10: 8 | J10: ="PI" & TEXT(E10, "000") -> PI057 | K10: =IFERROR(VLOOKUP(J10,'Inadimplencia - FEV 2025'!$A$5:$E$85,4,0),"0") -> 12654.41 | L10: =IFERROR(VLOOKUP(J10,'Inadimplencia - Out 2025'!$A$5:$E$85,4,0),"0") -> 15565.89 | M10: =L10-K10 -> 2911.48 | N10: =IF(L10>K10,"AUMENTOU","DIMINUIU") -> AUMENTOU
B11: 574.109.761-87 | C11: RAUL DE CASTRO ALVES | D11: Bougainville - BO | E11: 78 | F11: 2 | G11: Locação Temporária | H11: 8 | J11: ="BO" & TEXT(E11, "000") -> BO078 | K11: =IFERROR(VLOOKUP(J11,'Inadimplencia - FEV 2025'!$A$5:$E$85,4,0),"0") -> 12220.13 | L11: =IFERROR(VLOOKUP(J11,'Inadimplencia - Out 2025'!$A$5:$E$85,4,0),"0") -> 17241.53 | M11: =L11-K11 -> 5021.4 | N11: =IF(L11>K11,"AUMENTOU","DIMINUIU") -> AUMENTOU
B12: 598.221.121-49 | C12: LAERCIO PERY | D12: Jacarandás - JAC | E12: 33 | F12: 2 | G12: Residência | H12: 8 | J12: ="JA" & TEXT(E12, "000") -> JA033 | K12: =IFERROR(VLOOKUP(J12,'Inadimplencia - FEV 2025'!$A$5:$E$85,4,0),"0") -> 10618.13 | L12: =IFERROR(VLOOKUP(J12,'Inadimplencia - Out 2025'!$A$5:$E$85,4,0),"0") -> 11775.96 | M12: =L12-K12 -> 1157.83 | N12: =IF(L12>K12,"AUMENTOU","DIMINUIU") -> AUMENTOU
B13: 394.828.801-10 | C13: MARINA GONÇALVES VIEIRA | D13: Bougainville - BO | E13: 55 | F13: 2 | G13: Residência | H13: 8 | J13: ="BO" & TEXT(E13, "000") -> BO055 | K13: =IFERROR(VLOOKUP(J13,'Inadimplencia - FEV 2025'!$A$5:$E$85,4,0),"0") -> 10583.76 | L13: =IFERROR(VLOOKUP(J13,'Inadimplencia - Out 2025'!$A$5:$E$85,4,0),"0") -> 23136.52 | M13: =L13-K13 -> 12552.76 | N13: =IF(L13>K13,"AUMENTOU","DIMINUIU") -> AUMENTOU
B14: 435.480.831-53 | C14: MARIA DO SOCORRO BRAGA RAMALHO | D14: Azaléia - AZ | E14: 8 | F14: 2 | G14: Residência | H14: 8 | J14: ="AZ" & TEXT(E14, "000") -> AZ008 | K14: =IFERROR(VLOOKUP(J14,'Inadimplencia - FEV 2025'!$A$5:$E$85,4,0),"0") -> 9873.38 | L14: =IFERROR(VLOOKUP(J14,'Inadimplencia - Out 2025'!$A$5:$E$85,4,0),"0") -> 12140.85 | M14: =L14-K14 -> 2267.47 | N14: =IF(L14>K14,"AUMENTOU","DIMINUIU") -> AUMENTOU
B15: 375.788.711-53 | C15: CLOVIS PEREIRA DA SILVA | D15: Jacarandás - JAC | E15: 16 | F15: 2 | G15: Residência | H15: 8 | J15: ="JA" & TEXT(E15, "000") -> JA016 | K15: =IFERROR(VLOOKUP(J15,'Inadimplencia - FEV 2025'!$A$5:$E$85,4,0),"0") -> 9757.44 | L15: =IFERROR(VLOOKUP(J15,'Inadimplencia - Out 2025'!$A$5:$E$85,4,0),"0") -> 12567.56 | M15: =L15-K15 -> 2810.12 | N15: =IF(L15>K15,"AUMENTOU","DIMINUIU") -> AUMENTOU
B16: 984.282.681-34 | C16: MARIA DO SOCORRO BRAGA RAMALHO | D16: Azaléia - AZ | E16: 39 | F16: 2 | G16: Locação Temporária | H16: 4 | J16: ="AZ" & TEXT(E16, "000") -> AZ039 | K16: =IFERROR(VLOOKUP(J16,'Inadimplencia - FEV 2025'!$A$5:$E$85,4,0),"0") -> 9227.17 | L16: =IFERROR(VLOOKUP(J16,'Inadimplencia - Out 2025'!$A$5:$E$85,4,0),"0") -> 11456.08 | M16: =L16-K16 -> 2228.91 | N16: =IF(L16>K16,"AUMENTOU","DIMINUIU") -> AUMENTOU
B17: 732.336.258-04 | C17: JOSÉ MARIA FRAZÃO | D17: Azaléia - AZ | E17: 93 | F17: 2 | G17: Residência | H17: 8 | J17: ="AZ" & TEXT(E17, "000") -> AZ093 | K17: =IFERROR(VLOOKUP(J17,'Inadimplencia - FEV 2025'!$A$5:$E$85,4,0),"0") -> 8610.12 | L17: =IFERROR(VLOOKUP(J17,'Inadimplencia - Out 2025'!$A$5:$E$85,4,0),"0") -> 11929 | M17: =L17-K17 -> 3318.88 | N17: =IF(L17>K17,"AUMENTOU","DIMINUIU") -> AUMENTOU
B18: 010.461.441-20 | C18: ADRIANE DE SOUSA DURÃES | D18: Pitangueiras - PIT | E18: 72 | F18: 2 | G18: Residência | H18: 8 | J18: ="PI" & TEXT(E18, "000") -> PI072 | K18: =IFERROR(VLOOKUP(J18,'Inadimplencia - FEV 2025'!$A$5:$E$85,4,0),"0") -> 8253.66 | L18: =IFERROR(VLOOKUP(J18,'Inadimplencia - Out 2025'!$A$5:$E$85,4,0),"0") -> 12665.32 | M18: =L18-K18 -> 4411.66 | N18: =IF(L18>K18,"AUMENTOU","DIMINUIU") -> AUMENTOU
B19: 224.363.911-49 | C19: MARIA DO SOCORRO BRAGA RAMALHO | D19: Azaléia - AZ | E19: 23 | F19: 2 | G19: Locação Temporária | H19: 8 | J19: ="AZ" & TEXT(E19, "000") -> AZ023 | K19: =IFERROR(VLOOKUP(J19,'Inadimplencia - FEV 2025'!$A$5:$E$85,4,0),"0") -> 8051.65 | L19: =IFERROR(VLOOKUP(J19,'Inadimplencia - Out 2025'!$A$5:$E$85,4,0),"0") -> 10217.63 | M19: =L19-K19 -> 2165.98 | N19: =IF(L19>K19,"AUMENTOU","DIMINUIU") -> AUMENTOU
B20: 520.246.791-53 | J20: AZBAR | K20: =IFERROR(VLOOKUP(J20,'Inadimplencia - FEV 2025'!$A$5:$E$85,4,0),"0") -> 7186.21 | L20: =IFERROR(VLOOKUP(J20,'Inadimplencia - Out 2025'!$A$5:$E$85,4,0),"0") -> 7582.77 | M20: =L20-K20 -> 396.56 | N20: =IF(L20>K20,"AUMENTOU","DIMINUIU") -> AUMENTOU
B21: 059.604.601-49 | C21: KELIANE SANTOS ARANTES | D21: Gardênia - GA | E21: 40 | F21: 2 | G21: Residência | H21: 8 | J21: ="GA" & TEXT(E21, "000") -> GA040 | K21: =IFERROR(VLOOKUP(J21,'Inadimplencia - FEV 2025'!$A$5:$E$85,4,0),"0") -> 7070.41 | L21: =IFERROR(VLOOKUP(J21,'Inadimplencia - Out 2025'!$A$5:$E$85,4,0),"0") -> 10431.86 | M21: =L21-K21 -> 3361.45 | N21: =IF(L21>K21,"AUMENTOU","DIMINUIU") -> AUMENTOU
B22: 36.444.257/0001-80 | C22: MARIA DO SOCORRO BRAGA RAMALHO | D22: Azaléia - AZ | E22: 9 | F22: 2 | G22: Locação Temporária | H22: 8 | J22: ="AZ" & TEXT(E22, "000") -> AZ009 | K22: =IFERROR(VLOOKUP(J22,'Inadimplencia - FEV 2025'!$A$5:$E$85,4,0),"0") -> 6781.55 | L22: =IFERROR(VLOOKUP(J22,'Inadimplencia - Out 2025'!$A$5:$E$85,4,0),"0") -> 8868.32 | M22: =L22-K22 -> 2086.77 | N22: =IF(L22>K22,"AUMENTOU","DIMINUIU") -> AUMENTOU
B23: 36.444.257/0001-80 | C23: GILDENOU VALENTIM MARTINS | D23: Azaléia - AZ | E23: 47 | F23: 2 | G23: Residência | H23: 8 | J23: ="AZ" & TEXT(E23, "000") -> AZ047 | K23: =IFERROR(VLOOKUP(J23,'Inadimplencia - FEV 2025'!$A$5:$E$85,4,0),"0") -> 6673.95 | L23: =IFERROR(VLOOKUP(J23,'Inadimplencia - Out 2025'!$A$5:$E$85,4,0),"0") -> 8047.12 | M23: =L23-K23 -> 1373.17 | N23: =IF(L23>K23,"AUMENTOU","DIMINUIU") -> AUMENTOU
B24: 217.184.661-53 | C24: HENRIQUE MIRANDA DE ALMEIDA | D24: Gardênia - GA | E24: 38 | F24: 2 | G24: Residência | H24: 8 | J24: ="GA" & TEXT(E24, "000") -> GA038 | K24: =IFERROR(VLOOKUP(J24,'Inadimplencia - FEV 2025'!$A$5:$E$85,4,0),"0") -> 6414.44 | L24: =IFERROR(VLOOKUP(J24,'Inadimplencia - Out 2025'!$A$5:$E$85,4,0),"0") -> 0 | M24: =L24-K24 -> -6414.44 | N24: =IF(L24>K24,"AUMENTOU","DIMINUIU") -> AUMENTOU
B25: 423.581.751-53 | C25: OSMAR DA ROCHA CAMPOS | D25: Gardênia - GA | E25: 55 | F25: 2 | G25: Residência | H25: 8 | J25: ="GA" & TEXT(E25, "000") -> GA055 | K25: =IFERROR(VLOOKUP(J25,'Inadimplencia - FEV 2025'!$A$5:$E$85,4,0),"0") -> 5243.06 | L25: =IFERROR(VLOOKUP(J25,'Inadimplencia - Out 2025'!$A$5:$E$85,4,0),"0") -> 9460.95 | M25: =L25-K25 -> 4217.89 | N25: =IF(L25>K25,"AUMENTOU","DIMINUIU") -> AUMENTOU
B26: 864.594.061-20 | C26: SEBASTIÃO GONÇALVES REZENDE | D26: Azaléia - AZ | E26: 70 | F26: 2 | G26: Residência | H26: 8 | J26: ="AZ" & TEXT(E26, "000") -> AZ070 | K26: =IFERROR(VLOOKUP(J26,'Inadimplencia - FEV 2025'!$A$5:$E$85,4,0),"0") -> 5017.65 | L26: =IFERROR(VLOOKUP(J26,'Inadimplencia - Out 2025'!$A$5:$E$85,4,0),"0") -> 5240.42 | M26: =L26-K26 -> 222.77 | N26: =IF(L26>K26,"AUMENTOU","DIMINUIU") -> AUMENTOU
B27: 249.078.711-04 | C27: DIEGO MAURICIO ABREU SANTOS DA CONCEIÇÃO | D27: Orquídeas - OR | E27: 35 | F27: 2 | G27: Residência | H27: 8 | J27: ="OR" & TEXT(E27, "000") -> OR035 | K27: =IFERROR(VLOOKUP(J27,'Inadimplencia - FEV 2025'!$A$5:$E$85,4,0),"0") -> 4622.99 | L27: =IFERROR(VLOOKUP(J27,'Inadimplencia - Out 2025'!$A$5:$E$85,4,0),"0") -> 7687.41 | M27: =L27-K27 -> 3064.42 | N27: =IF(L27>K27,"AUMENTOU","DIMINUIU") -> AUMENTOU
B28: 249.078.711-04 | C28: GUILHERME CARVALHO VILLETE | D28: Bougainville - BO | E28: 86 | F28: 2 | G28: Residência | H28: 8 | J28: ="BO" & TEXT(E28, "000") -> BO086 | K28: =IFERROR(VLOOKUP(J28,'Inadimplencia - FEV 2025'!$A$5:$E$85,4,0),"0") -> 4609.47 | L28: =IFERROR(VLOOKUP(J28,'Inadimplencia - Out 2025'!$A$5:$E$85,4,0),"0") -> 7110.71 | M28: =L28-K28 -> 2501.24 | N28: =IF(L28>K28,"AUMENTOU","DIMINUIU") -> AUMENTOU
B29: 386.790.601-78 | C29: CRISTIANO ALVES DA SILVA | D29: Bougainville - BO | E29: 110 | F29: 2 | G29: Locação Temporária | H29: 8 | J29: ="BO" & TEXT(E29, "000") -> BO110 | K29: =IFERROR(VLOOKUP(J29,'Inadimplencia - FEV 2025'!$A$5:$E$85,4,0),"0") -> 3743.39 | L29: =IFERROR(VLOOKUP(J29,'Inadimplencia - Out 2025'!$A$5:$E$85,4,0),"0") -> 3950.82 | M29: =L29-K29 -> 207.43 | N29: =IF(L29>K29,"AUMENTOU","DIMINUIU") -> AUMENTOU
B30: 871.709.061-04 | C30: AURIDEA CASTRO FALCÃO FERNANDES | D30: Pitangueiras - PIT | E30: 4 | F30: 2 | G30: Residência | H30: 8 | J30: ="PI" & TEXT(E30, "000") -> PI004 | K30: =IFERROR(VLOOKUP(J30,'Inadimplencia - FEV 2025'!$A$5:$E$85,4,0),"0") -> 2845.77 | L30: =IFERROR(VLOOKUP(J30,'Inadimplencia - Out 2025'!$A$5:$E$85,4,0),"0") -> 3936.36 | M30: =L30-K30 -> 1090.59 | N30: =IF(L30>K30,"AUMENTOU","DIMINUIU") -> AUMENTOU
B31: 346.953.541-87 | C31: WILLIAN DEL. DUQUE DE LA TOUR E ALEN | D31: Jacarandás - JAC | E31: 44 | F31: 2 | G31: Residência | H31: 8 | J31: ="JA" & TEXT(E31, "000") -> JA044 | K31: =IFERROR(VLOOKUP(J31,'Inadimplencia - FEV 2025'!$A$5:$E$85,4,0),"0") -> 2785.3 | L31: =IFERROR(VLOOKUP(J31,'Inadimplencia - Out 2025'!$A$5:$E$85,4,0),"0") -> 3366.22 | M31: =L31-K31 -> 580.92 | N31: =IF(L31>K31,"AUMENTOU","DIMINUIU") -> AUMENTOU
B32: 036.667.431-53 | C32: FLORA LORENÇO SILVA | D32: Azaléia - AZ | E32: 87 | F32: 2 | G32: Residência | H32: 8 | J32: ="AZ" & TEXT(E32, "000") -> AZ087 | K32: =IFERROR(VLOOKUP(J32,'Inadimplencia - FEV 2025'!$A$5:$E$85,4,0),"0") -> 2406.02 | L32: =IFERROR(VLOOKUP(J32,'Inadimplencia - Out 2025'!$A$5:$E$85,4,0),"0") -> 8065.15 | M32: =L32-K32 -> 5659.13 | N32: =IF(L32>K32,"AUMENTOU","DIMINUIU") -> AUMENTOU
B33: 009.336.601-97 | C33: MARGARIDA MARIA DE SOUSA | D33: Pitangueiras - PIT | E33: 80 | F33: 2 | G33: Residência | H33: 8 | J33: ="PI" & TEXT(E33, "000") -> PI080 | K33: =IFERROR(VLOOKUP(J33,'Inadimplencia - FEV 2025'!$A$5:$E$85,4,0),"0") -> 2174.77 | L33: =IFERROR(VLOOKUP(J33,'Inadimplencia - Out 2025'!$A$5:$E$85,4,0),"0") -> 2383.81 | M33: =L33-K33 -> 209.04 | N33: =IF(L33>K33,"AUMENTOU","DIMINUIU") -> AUMENTOU
B34: 073.061.211-20 | C34: DEUSIRENE ALVES DA SILVA | D34: Orquídeas - OR | E34: 47 | F34: 2 | G34: Residência | H34: 8 | J34: ="OR" & TEXT(E34, "000") -> OR047 | K34: =IFERROR(VLOOKUP(J34,'Inadimplencia - FEV 2025'!$A$5:$E$85,4,0),"0") -> 1927.85 | L34: =IFERROR(VLOOKUP(J34,'Inadimplencia - Out 2025'!$A$5:$E$85,4,0),"0") -> 2035.7 | M34: =L34-K34 -> 107.85 | N34: =IF(L34>K34,"AUMENTOU","DIMINUIU") -> AUMENTOU
B35: 059.604.601-49 | C35: CLEMENTE MARQUES DA SILVA | D35: Pitangueiras - PIT | E35: 42 | F35: 2 | G35: Residência | H35: 8 | J35: ="PI" & TEXT(E35, "000") -> PI042 | K35: =IFERROR(VLOOKUP(J35,'Inadimplencia - FEV 2025'!$A$5:$E$85,4,0),"0") -> 1662.99 | L35: =IFERROR(VLOOKUP(J35,'Inadimplencia - Out 2025'!$A$5:$E$85,4,0),"0") -> 2230.53 | M35: =L35-K35 -> 567.54 | N35: =IF(L35>K35,"AUMENTOU","DIMINUIU") -> AUMENTOU
B36: 267.274.471-87 | C36: JAIR JUNIOR CALACIO JUSTINO | D36: Orquídeas - OR | E36: 49 | F36: 2 | G36: Residência | H36: 8 | J36: ="OR" & TEXT(E36, "000") -> OR049 | K36: =IFERROR(VLOOKUP(J36,'Inadimplencia - FEV 2025'!$A$5:$E$85,4,0),"0") -> 1099.57 | L36: =IFERROR(VLOOKUP(J36,'Inadimplencia - Out 2025'!$A$5:$E$85,4,0),"0") -> 3366.22 | M36: =L36-K36 -> 2266.65 | N36: =IF(L36>K36,"AUMENTOU","DIMINUIU") -> AUMENTOU
B37: 508.320.001-59 | C37: YANKO BATISTA LLOBET | D37: Orquídeas - OR | E37: 71 | F37: 2 | G37: Residência | H37: 8 | J37: ="OR" & TEXT(E37, "000") -> OR071 | K37: =IFERROR(VLOOKUP(J37,'Inadimplencia - FEV 2025'!$A$5:$E$85,4,0),"0") -> 1092.19 | L37: =IFERROR(VLOOKUP(J37,'Inadimplencia - Out 2025'!$A$5:$E$85,4,0),"0") -> 5084 | M37: =L37-K37 -> 3991.81 | N37: =IF(L37>K37,"AUMENTOU","DIMINUIU") -> AUMENTOU
B38: 210.855.951-53 | C38: SEBASTIÃO LUIZ DE VASCONCELOS FILHO | D38: Azaléia - AZ | E38: 26 | F38: 2 | G38: Residência | H38: 8 | J38: ="AZ" & TEXT(E38, "000") -> AZ026 | K38: =IFERROR(VLOOKUP(J38,'Inadimplencia - FEV 2025'!$A$5:$E$85,4,0),"0") -> 1092.19 | L38: =IFERROR(VLOOKUP(J38,'Inadimplencia - Out 2025'!$A$5:$E$85,4,0),"0") -> 3375.61 | M38: =L38-K38 -> 2283.42 | N38: =IF(L38>K38,"AUMENTOU","DIMINUIU") -> AUMENTOU
B39: 358.148.101-49 | C39: FRANCISCO CARLOS DE CASTRO E OUTROS | D39: Orquídeas - OR | E39: 13 | F39: 2 | G39: Residência | H39: 8 | J39: ="OR" & TEXT(E39, "000") -> OR013 | K39: =IFERROR(VLOOKUP(J39,'Inadimplencia - FEV 2025'!$A$5:$E$85,4,0),"0") -> 1092.19 | L39: =IFERROR(VLOOKUP(J39,'Inadimplencia - Out 2025'!$A$5:$E$85,4,0),"0") -> 1147.64 | M39: =L39-K39 -> 55.45 | N39: =IF(L39>K39,"AUMENTOU","DIMINUIU") -> AUMENTOU
B40: 020.164.871-78 | C40: MANOEL FRANCISCO DA SILVA | D40: Pitangueiras - PIT | E40: 71 | F40: 2 | G40: Residência | H40: 8 | J40: ="PI" & TEXT(E40, "000") -> PI071 | K40: =IFERROR(VLOOKUP(J40,'Inadimplencia - FEV 2025'!$A$5:$E$85,4,0),"0") -> 674.49 | L40: =IFERROR(VLOOKUP(J40,'Inadimplencia - Out 2025'!$A$5:$E$85,4,0),"0") -> 1265.44 | M40: =L40-K40 -> 590.95 | N40: =IF(L40>K40,"AUMENTOU","DIMINUIU") -> AUMENTOU
...
